---------------------------------------------------------------------------TypeError                                 Traceback (most recent call last)File d:\agentenv\Lib\site-packages\pydantic\main.py:343, in pydantic.main.BaseModel.__init__()  TypeError: __dict__ must be set to a dictionary, not a 'NoneType' The above exception was the direct cause of the following exception: TypeError                                 Traceback (most recent call last)Cell In[6], line 19      1 from langchain_core.messages import (      2     AIMessage,      3     AIMessageChunk,   (...)     17     ToolMessageChunk,     18 )---> 19 chat_caller = IAS_ChatCaller(     20     engine="gpt-3.5-turbo"
has context menu
