ERROR:root:Error during index processTraceback (most recent call last):  File "C:\Users\deepa05\AppData\Local\Temp\ipykernel_14240\3817039915.py", line 180, in load    extra_image_summary, extra_image_uuid=self.ingest_image(path_to_ingest="/tables/img")                                          ^^^^^^^^^^^^^^^^^^^^^^^^^^^^^^^^^^^^^^^^^^^^^^^  File "C:\Users\deepa05\AppData\Local\Temp\ipykernel_14240\3817039915.py", line 104, in ingest_image    "id_key": img_ids[sorted(os.listdir(path)).index(img_file)],
